Workbook

Sheet Adecco HR Analytics
A1: Age | B1: Attrition | C1: AttritionFlag | D1: BusinessTravel | E1: DailyRate | F1: Department | G1: DistanceFromHome | H1: Education | I1: EducationField | J1: EmployeeCount | K1: EmployeeNumber | L1: EnvironmentSatisfaction | M1: Gender | N1: HourlyRate | O1: JobInvolvement | P1: JobLevel | Q1: JobRole | R1: JobSatisfaction | S1: MaritalStatus | T1: MonthlyIncome | U1: MonthlyRate | V1: NumCompaniesWorked | W1: Over18 | X1: OverTime | Y1: PercentSalaryHike | Z1: PerformanceRating | AA1: RelationshipSatisfaction | AB1: StandardHours | AC1: StockOptionLevel | AD1: TotalWorkingYears | AE1: TrainingTimesLastYear | AF1: WorkLifeBalance | AG1: YearsAtCompany | AH1: YearsInCurrentRole | AI1: YearsSinceLastPromotion | AJ1: YearsWithCurrManager
A2: 41 | B2: Yes | C2: =IF(Table1[[#This Row],[Attrition]]="Yes",1,0) -> 1 | D2: Travel_Rarely | E2: 1102 | F2: Sales | G2: 1 | H2: 2 | I2: Life Sciences | J2: 1 | K2: 1 | L2: 2 | M2: Female | N2: 94 | O2: 3 | P2: 2 | Q2: Sales Executive | R2: 4 | S2: Single | T2: 5993 | U2: 19479 | V2: 8 | W2: Y | X2: Yes | Y2: 11 | Z2: 3 | AA2: 1 | AB2: 80 | AC2: 0 | AD2: 8 | AE2: 0 | AF2: 1 | AG2: 6 | AH2: 4 | AI2: 0 | AJ2: 5
A3: 49 | B3: No | C3: =IF(Table1[[#This Row],[Attrition]]="Yes",1,0) -> 0 | D3: Travel_Frequently | E3: 279 | F3: Research & Development | G3: 8 | H3: 1 | I3: Life Sciences | J3: 1 | K3: 2 | L3: 3 | M3: Male | N3: 61 | O3: 2 | P3: 2 | Q3: Research Scientist | R3: 2 | S3: Married | T3: 5130 | U3: 24907 | V3: 1 | W3: Y | X3: No | Y3: 23 | Z3: 4 | AA3: 4 | AB3: 80 | AC3: 1 | AD3: 10 | AE3: 3 | AF3: 3 | AG3: 10 | AH3: 7 | AI3: 1 | AJ3: 7
A4: 37 | B4: Yes | C4: =IF(Table1[[#This Row],[Attrition]]="Yes",1,0) -> 1 | D4: Travel_Rarely | E4: 1373 | F4: Research & Development | G4: 2 | H4: 2 | I4: Other | J4: 1 | K4: 4 | L4: 4 | M4: Male | N4: 92 | O4: 2 | P4: 1 | Q4: Laboratory Technician | R4: 3 | S4: Single | T4: 2090 | U4: 2396 | V4: 6 | W4: Y | X4: Yes | Y4: 15 | Z4: 3 | AA4: 2 | AB4: 80 | AC4: 0 | AD4: 7 | AE4: 3 | AF4: 3 | AG4: 0 | AH4: 0 | AI4: 0 | AJ4: 0
A5: 33 | B5: No | C5: =IF(Table1[[#This Row],[Attrition]]="Yes",1,0) -> 0 | D5: Travel_Frequently | E5: 1392 | F5: Research & Development | G5: 3 | H5: 4 | I5: Life Sciences | J5: 1 | K5: 5 | L5: 4 | M5: Female | N5: 56 | O5: 3 | P5: 1 | Q5: Research Scientist | R5: 3 | S5: Married | T5: 2909 | U5: 23159 | V5: 1 | W5: Y | X5: Yes | Y5: 11 | Z5: 3 | AA5: 3 | AB5: 80 | AC5: 0 | AD5: 8 | AE5: 3 | AF5: 3 | AG5: 8 | AH5: 7 | AI5: 3 | AJ5: 0
A6: 27 | B6: No | C6: =IF(Table1[[#This Row],[Attrition]]="Yes",1,0) -> 0 | D6: Travel_Rarely | E6: 591 | F6: Research & Development | G6: 2 | H6: 1 | I6: Medical | J6: 1 | K6: 7 | L6: 1 | M6: Male | N6: 40 | O6: 3 | P6: 1 | Q6: Laboratory Technician | R6: 2 | S6: Married | T6: 3468 | U6: 16632 | V6: 9 | W6: Y | X6: No | Y6: 12 | Z6: 3 | AA6: 4 | AB6: 80 | AC6: 1 | AD6: 6 | AE6: 3 | AF6: 3 | AG6: 2 | AH6: 2 | AI6: 2 | AJ6: 2
A7: 32 | B7: No | C7: =IF(Table1[[#This Row],[Attrition]]="Yes",1,0) -> 0 | D7: Travel_Frequently | E7: 1005 | F7: Research & Development | G7: 2 | H7: 2 | I7: Life Sciences | J7: 1 | K7: 8 | L7: 4 | M7: Male | N7: 79 | O7: 3 | P7: 1 | Q7: Laboratory Technician | R7: 4 | S7: Single | T7: 3068 | U7: 11864 | V7: 0 | W7: Y | X7: No | Y7: 13 | Z7: 3 | AA7: 3 | AB7: 80 | AC7: 0 | AD7: 8 | AE7: 2 | AF7: 2 | AG7: 7 | AH7: 7 | AI7: 3 | AJ7: 6
A8: 59 | B8: No | C8: =IF(Table1[[#This Row],[Attrition]]="Yes",1,0) -> 0 | D8: Travel_Rarely | E8: 1324 | F8: Research & Development | G8: 3 | H8: 3 | I8: Medical | J8: 1 | K8: 10 | L8: 3 | M8: Female | N8: 81 | O8: 4 | P8: 1 | Q8: Laboratory Technician | R8: 1 | S8: Married | T8: 2670 | U8: 9964 | V8: 4 | W8: Y | X8: Yes | Y8: 20 | Z8: 4 | AA8: 1 | AB8: 80 | AC8: 3 | AD8: 12 | AE8: 3 | AF8: 2 | AG8: 1 | AH8: 0 | AI8: 0 | AJ8: 0
A9: 30 | B9: No | C9: =IF(Table1[[#This Row],[Attrition]]="Yes",1,0) -> 0 | D9: Travel_Rarely | E9: 1358 | F9: Research & Development | G9: 24 | H9: 1 | I9: Life Sciences | J9: 1 | K9: 11 | L9: 4 | M9: Male | N9: 67 | O9: 3 | P9: 1 | Q9: Laboratory Technician | R9: 3 | S9: Divorced | T9: 2693 | U9: 13335 | V9: 1 | W9: Y | X9: No | Y9: 22 | Z9: 4 | AA9: 2 | AB9: 80 | AC9: 1 | AD9: 1 | AE9: 2 | AF9: 3 | AG9: 1 | AH9: 0 | AI9: 0 | AJ9: 0
A10: 38 | B10: No | C10: =IF(Table1[[#This Row],[Attrition]]="Yes",1,0) -> 0 | D10: Travel_Frequently | E10: 216 | F10: Research & Development | G10: 23 | H10: 3 | I10: Life Sciences | J10: 1 | K10: 12 | L10: 4 | M10: Male | N10: 44 | O10: 2 | P10: 3 | Q10: Manufacturing Director | R10: 3 | S10: Single | T10: 9526 | U10: 8787 | V10: 0 | W10: Y | X10: No | Y10: 21 | Z10: 4 | AA10: 2 | AB10: 80 | AC10: 0 | AD10: 10 | AE10: 2 | AF10: 3 | AG10: 9 | AH10: 7 | AI10: 1 | AJ10: 8
A11: 36 | B11: No | C11: =IF(Table1[[#This Row],[Attrition]]="Yes",1,0) -> 0 | D11: Travel_Rarely | E11: 1299 | F11: Research & Development | G11: 27 | H11: 3 | I11: Medical | J11: 1 | K11: 13 | L11: 3 | M11: Male | N11: 94 | O11: 3 | P11: 2 | Q11: Healthcare Representative | R11: 3 | S11: Married | T11: 5237 | U11: 16577 | V11: 6 | W11: Y | X11: No | Y11: 13 | Z11: 3 | AA11: 2 | AB11: 80 | AC11: 2 | AD11: 17 | AE11: 3 | AF11: 2 | AG11: 7 | AH11: 7 | AI11: 7 | AJ11: 7
A12: 35 | B12: No | C12: =IF(Table1[[#This Row],[Attrition]]="Yes",1,0) -> 0 | D12: Travel_Rarely | E12: 809 | F12: Research & Development | G12: 16 | H12: 3 | I12: Medical | J12: 1 | K12: 14 | L12: 1 | M12: Male | N12: 84 | O12: 4 | P12: 1 | Q12: Laboratory Technician | R12: 2 | S12: Married | T12: 2426 | U12: 16479 | V12: 0 | W12: Y | X12: No | Y12: 13 | Z12: 3 | AA12: 3 | AB12: 80 | AC12: 1 | AD12: 6 | AE12: 5 | AF12: 3 | AG12: 5 | AH12: 4 | AI12: 0 | AJ12: 3
A13: 29 | B13: No | C13: =IF(Table1[[#This Row],[Attrition]]="Yes",1,0) -> 0 | D13: Travel_Rarely | E13: 153 | F13: Research & Development | G13: 15 | H13: 2 | I13: Life Sciences | J13: 1 | K13: 15 | L13: 4 | M13: Female | N13: 49 | O13: 2 | P13: 2 | Q13: Laboratory Technician | R13: 3 | S13: Single | T13: 4193 | U13: 12682 | V13: 0 | W13: Y | X13: Yes | Y13: 12 | Z13: 3 | AA13: 4 | AB13: 80 | AC13: 0 | AD13: 10 | AE13: 3 | AF13: 3 | AG13: 9 | AH13: 5 | AI13: 0 | AJ13: 8
... A1471: 34 | B1471: No | C1471: =IF(Table1[[#This Row],[Attrition]]="Yes",1,0) -> 0 | D1471: Travel_Rarely | E1471: 628 | F1471: Research & Development | G1471: 8 | H1471: 3 | I1471: Medical | J1471: 1 | K1471: 2068 | L1471: 2 | M1471: Male | N1471: 82 | O1471: 4 | P1471: 2 | Q1471: Laboratory Technician | R1471: 3 | S1471: Married | T1471: 4404 | U1471: 10228 | V1471: 2 | W1471: Y | X1471: No | Y1471: 12 | Z1471: 3 | AA1471: 1 | AB1471: 80 | AC1471: 0 | AD1471: 6 | AE1471: 3 | AF1471: 4 | AG1471: 4 | AH1471: 3 | AI1471: 1 | AJ1471: 2

Sheet Assignment Solutions
A1: Adecco HR Analytics — Excel End-to-End Assignment
A4: Basic-Level Questions (Excel-Oriented)
A6: 1.1: Overall Attrition Rate
A8: Question | B8: Formula
A9: Count employees who left | B9: =COUNTIF('Adecco HR Analytics'!B:B,"Yes") -> 237
A10: Count total employees | B10: =COUNTA(Table1[Age]) -> 1470
A11: Calculate attrition rate | B11: =B9/B10 -> 0.16122449
A13: Meaning : The overall attrition rate is 16.12%, meaning approximately 16 out of every 100 employees have left the company.
A16: Basic Question 1.3 – 1.10
A18: Question | B18: Formula
A19: 1.3: Average age of employees who left | B19: =AVERAGEIF('Adecco HR Analytics'!B:B,"yes",'Adecco HR Analytics'!A:A) -> 33.607595
A20: 1.6: Average monthly income of employees who left | B20: =AVERAGEIF('Adecco HR Analytics'!B:B,"Yes",'Adecco HR Analytics'!T:T) -> 4787.0928
A21: 1.9: How many employees work overtime | B21: =COUNTIF('Adecco HR Analytics'!X:X,"Yes") -> 416
A22: 1.10: Average years at company | B22: =AVERAGE('Adecco HR Analytics'!AG:AG) -> 7.0081633
A25: Medium-Level Questions (Excel-Oriented)
A27: Question | B27: Formula | C27: Meaning
A28: 2.1: Top 3 factors correlated with attrition
A29: Age Correlated: | B29: =CORREL('Adecco HR Analytics'!A:A,'Adecco HR Analytics'!AJ:AJ) -> 0.2020886 | C29: These are the strongest absolute correlations among the numeric factors tested.
A30: MonthlyIncome Correlated: | B30: =CORREL('Adecco HR Analytics'!T:T,'Adecco HR Analytics'!AJ:AJ) -> 0.34407888
A31: YearsAtCompany Correlated: | B31: =CORREL('Adecco HR Analytics'!AG:AG,'Adecco HR Analytics'!AJ:AJ) -> 0.76921243
A34: Conclusion & Actions
A36: • The main issue is employee attrition, with the case specifically highlighting junior sales employees.
A37: • Start retention work with the department showing the highest calculated attrition rate.
A38: • Review overtime, job satisfaction, job involvement, compensation, tenure and career progression together rather than relying on one metric.
A39: • Use the correlation results as signals for further investigation, correlation alone does not prove that a factor causes attrition.
A40: • Present the findings to HR and senior management and turn the strongest findings into targeted retention actions.

Sheet Pivot Analysis
A1: 1.2: Department-wise Attrition
A4: Count of EmployeeNumber | B4: Attrition
A5: Department | B5: No | C5: Yes | D5: Grand Total | E5: Attrition Rate
A6: Human Resources | B6: 51 | C6: 12 | D6: 63 | E6: =GETPIVOTDATA("EmployeeNumber",$A$4,"Attrition","Yes","Department","Human Resources")/GETPIVOTDATA("EmployeeNumber",$A$4,"Department","Human Resources") -> 0.19047619
A7: Research & Development | B7: 828 | C7: 133 | D7: 961 | E7: =GETPIVOTDATA("EmployeeNumber",$A$4,"Attrition","Yes","Department","Research & Development")/GETPIVOTDATA("EmployeeNumber",$A$4,"Department","Research & Development") -> 0.1383975
A8: Sales | B8: 354 | C8: 92 | D8: 446 | E8: =GETPIVOTDATA("EmployeeNumber",$A$4,"Attrition","Yes","Department","Sales")/GETPIVOTDATA("EmployeeNumber",$A$4,"Department","Sales") -> 0.20627803
A9: Grand Total | B9: 1233 | C9: 237 | D9: 1470 | E9: =GETPIVOTDATA("EmployeeNumber",$A$4,"Attrition","Yes")/GETPIVOTDATA("EmployeeNumber",$A$4) -> 0.16122449
A12: 1.4: Average Job Satisfaction by Job Role
A15: JobRole | B15: Average of JobSatisfaction
A16: Healthcare Representative | B16: 2.7862595
A17: Research Scientist | B17: 2.7739726
A18: Sales Executive | B18: 2.7546012
A19: Sales Representative | B19: 2.7349398
A20: Manager | B20: 2.7058824
A21: Research Director | B21: 2.7
A22: Laboratory Technician | B22: 2.6911197
A23: Manufacturing Director | B23: 2.6827586
A24: Human Resources | B24: 2.5576923
A25: Grand Total | B25: 2.7285714
A28: 1.5: Gender-wise Attrition
A31: Count of EmployeeNumber | B31: Attrition
A32: Gender | B32: No | C32: Yes | D32: Grand Total | E32: Attrition Rate
A33: Female | B33: 501 | C33: 87 | D33: 588 | E33: =GETPIVOTDATA("EmployeeNumber",$A$31,"Attrition","Yes","Gender","Female")/GETPIVOTDATA("EmployeeNumber",$A$31,"Gender","Female") -> 0.14795918
A34: Male | B34: 732 | C34: 150 | D34: 882 | E34: =GETPIVOTDATA("EmployeeNumber",$A$31,"Attrition","Yes","Gender","Male")/GETPIVOTDATA("EmployeeNumber",$A$31,"Gender","Male") -> 0.17006803
A35: Grand Total | B35: 1233 | C35: 237 | D35: 1470 | E35: =GETPIVOTDATA("EmployeeNumber",$A$31,"Attrition","Yes")/GETPIVOTDATA("EmployeeNumber",$A$31) -> 0.16122449
A38: 2.2: Attrition by Job Involvement
A41: Count of EmployeeNumber | B41: Attrition
A42: JobInvolvement | B42: No | C42: Yes | D42: Grand Total | E42: Attrition Rate
A43: 1 | B43: 55 | C43: 28 | D43: 83 | E43: =GETPIVOTDATA("EmployeeNumber",$A$41,"Attrition","Yes","JobInvolvement",1)/GETPIVOTDATA("EmployeeNumber",$A$41,"JobInvolvement",1) -> 0.3373494
A44: 2 | B44: 304 | C44: 71 | D44: 375 | E44: =GETPIVOTDATA("EmployeeNumber",$A$41,"Attrition","Yes","JobInvolvement",2)/GETPIVOTDATA("EmployeeNumber",$A$41,"JobInvolvement",2) -> 0.18933333
A45: 3 | B45: 743 | C45: 125 | D45: 868 | E45: =GETPIVOTDATA("EmployeeNumber",$A$41,"Attrition","Yes","JobInvolvement",3)/GETPIVOTDATA("EmployeeNumber",$A$41,"JobInvolvement",3) -> 0.14400922
A46: 4 | B46: 131 | C46: 13 | D46: 144 | E46: =GETPIVOTDATA("EmployeeNumber",$A$41,"Attrition","Yes","JobInvolvement",4)/GETPIVOTDATA("EmployeeNumber",$A$41,"JobInvolvement",4) -> 0.090277778
A47: Grand Total | B47: 1233 | C47: 237 | D47: 1470 | E47: =GETPIVOTDATA("EmployeeNumber",$A$41,"Attrition","Yes")/GETPIVOTDATA("EmployeeNumber",$A$41) -> 0.16122449
A50: 2.4: Marital Status and Attrition
A53: Count of EmployeeNumber | B53: Attrition
A54: MaritalStatus | B54: No | C54: Yes | D54: Grand Total | E54: Attrition Rate
A55: Divorced | B55: 294 | C55: 33 | D55: 327 | E55: =GETPIVOTDATA("EmployeeNumber",$A$53,"Attrition","Yes","MaritalStatus","Divorced")/GETPIVOTDATA("EmployeeNumber",$A$53,"MaritalStatus","Divorced") -> 0.10091743
A56: Married | B56: 589 | C56: 84 | D56: 673 | E56: =GETPIVOTDATA("EmployeeNumber",$A$53,"Attrition","Yes","MaritalStatus","Married")/GETPIVOTDATA("EmployeeNumber",$A$53,"MaritalStatus","Married") -> 0.12481426
A57: Single | B57: 350 | C57: 120 | D57: 470 | E57: =GETPIVOTDATA("EmployeeNumber",$A$53,"Attrition","Yes","MaritalStatus","Single")/GETPIVOTDATA("EmployeeNumber",$A$53,"MaritalStatus","Single") -> 0.25531915
A58: Grand Total | B58: 1233 | C58: 237 | D58: 1470 | E58: =GETPIVOTDATA("EmployeeNumber",$A$53,"Attrition","Yes")/GETPIVOTDATA("EmployeeNumber",$A$53) -> 0.16122449
...

Sheet Chart Analysis
A1: 1.7: Distance vs Attrition
A21: 1.8: Performance Rating Distribution
A24: PerformanceRating | B24: Count of EmployeeNumber
A25: 3 | B25: 1244
A26: 4 | B26: 226
A27: Grand Total | B27: 1470
A46: 2.3: Age vs Job Satisfaction
A66: 2.6: Work-Life Balance vs Performance
A86: 2.8: Tenure vs Job Satisfaction
A106: 2.10: Years Since Last Promotion vs Performance
